2021-07-26 10:07:28,049 ERROR: Catch an exception.
Traceback (most recent call last):
  File "<ipython-input-14-065b1344c4bb>", line 38, in <module>
    pd.read_csv('ewrfwefegv.csv')
  File "C:\Users\show1\anaconda3\lib\site-packages\pandas\io\parsers.py", line 610, in read_csv
    return _read(filepath_or_buffer, kwds)
  File "C:\Users\show1\anaconda3\lib\site-packages\pandas\io\parsers.py", line 462, in _read
    parser = TextFileReader(filepath_or_buffer, **kwds)
  File "C:\Users\show1\anaconda3\lib\site-packages\pandas\io\parsers.py", line 819, in __init__
    self._engine = self._make_engine(self.engine)
  File "C:\Users\show1\anaconda3\lib\site-packages\pandas\io\parsers.py", line 1050, in _make_engine
    return mapping[engine](self.f, **self.options)  # type: ignore[call-arg]
  File "C:\Users\show1\anaconda3\lib\site-packages\pandas\io\parsers.py", line 1867, in __init__
    self._open_handles(src, kwds)
  File "C:\Users\show1\anaconda3\lib\site-packages\pandas\io\parsers.py", line 1362, in _open_handles
    self.handles = get_handle(
  File "C:\Users\show1\anaconda3\lib\site-packages\pandas\io\common.py", line 642, in get_handle
    handle = open(
FileNotFoundError: [Errno 2] No such file or directory: 'ewrfwefegv.csv'
2021-07-26 10:08:21,571 ERROR: Catch an exception.
Traceback (most recent call last):
  File "<ipython-input-15-b6411d110273>", line 38, in <module>
    pd.read_csv('ewrfwefegv.csv')
  File "C:\Users\show1\anaconda3\lib\site-packages\pandas\io\parsers.py", line 610, in read_csv
    return _read(filepath_or_buffer, kwds)
  File "C:\Users\show1\anaconda3\lib\site-packages\pandas\io\parsers.py", line 462, in _read
    parser = TextFileReader(filepath_or_buffer, **kwds)
  File "C:\Users\show1\anaconda3\lib\site-packages\pandas\io\parsers.py", line 819, in __init__
    self._engine = self._make_engine(self.engine)
  File "C:\Users\show1\anaconda3\lib\site-packages\pandas\io\parsers.py", line 1050, in _make_engine
    return mapping[engine](self.f, **self.options)  # type: ignore[call-arg]
  File "C:\Users\show1\anaconda3\lib\site-packages\pandas\io\parsers.py", line 1867, in __init__
    self._open_handles(src, kwds)
  File "C:\Users\show1\anaconda3\lib\site-packages\pandas\io\parsers.py", line 1362, in _open_handles
    self.handles = get_handle(
  File "C:\Users\show1\anaconda3\lib\site-packages\pandas\io\common.py", line 642, in get_handle
    handle = open(
FileNotFoundError: [Errno 2] No such file or directory: 'ewrfwefegv.csv'
2021-07-26 19:22:48,539 ERROR: Catch an exception.
Traceback (most recent call last):
  File "C:\Users\show1\anaconda3\lib\site-packages\pandas\core\indexes\base.py", line 3080, in get_loc
    return self._engine.get_loc(casted_key)
  File "pandas\_libs\index.pyx", line 70, in pandas._libs.index.IndexEngine.get_loc
  File "pandas\_libs\index.pyx", line 101, in pandas._libs.index.IndexEngine.get_loc
  File "pandas\_libs\hashtable_class_helper.pxi", line 1625, in pandas._libs.hashtable.Int64HashTable.get_item
  File "pandas\_libs\hashtable_class_helper.pxi", line 1632, in pandas._libs.hashtable.Int64HashTable.get_item
KeyError: 18

The above exception was the direct cause of the following exception:

Traceback (most recent call last):
  File "<ipython-input-50-9d627b30e59f>", line 232, in <module>
    year = str(int(d[i].split('/')[0])+1911)
  File "C:\Users\show1\anaconda3\lib\site-packages\pandas\core\series.py", line 853, in __getitem__
    return self._get_value(key)
  File "C:\Users\show1\anaconda3\lib\site-packages\pandas\core\series.py", line 961, in _get_value
    loc = self.index.get_loc(label)
  File "C:\Users\show1\anaconda3\lib\site-packages\pandas\core\indexes\base.py", line 3082, in get_loc
    raise KeyError(key) from err
KeyError: 18
